Workbook
Name Slicer_Delivery_Status: #N/A
Name Slicer_Payment_Method: #N/A
Name Slicer_Region: #N/A

Sheet Orders
A1: Order ID | B1: Customer ID | C1: Product ID | D1: Region | E1: Sale Price/Unit | F1: Quantity | G1: Total Amount | H1: Payment Method | I1: Delivery Status | J1: Fulfillment Partner | K1: Order Date | L1: Delivery Date | M1: Cancel Date | N1: Is cancelled | O1: Product category | P1: Avg. delivery date | Q1: customer name | R1: Delivery performance | S1: Product name
A2: ORD0001 | B2: CUST021 | C2: PROD012 | D2: North | E2: 44 | F2: 1 | G2: 44 | H2: Apple Pay | I2: Cancelled | J2: DHL | K2: 45291 | M2: 45293 | N2: =IF(OR(I2="Cancelled",M2<>""),"Yes","No") -> Yes | O2: =_xlfn.XLOOKUP(Orders!C2,'Product Master'!$A$1:$A$23,'Product Master'!$C$1:$C$23) -> Home | P2: =IF(L2<>"",L2-K2,"NA") -> NA | Q2: =_xlfn.XLOOKUP(B2,'Customer Master'!$A$1:$A$50,'Customer Master'!$B$1:$B$50) -> Zoe Mitchell | R2: {=_xlfn.IFS(P2="NA","NA",P2<=2,"FAST",P2>2,"SLOW")} -> NA | S2: =_xlfn.XLOOKUP(Orders!C2,'Product Master'!$A$1:$A$23,'Product Master'!$B$1:$B$23) -> Lamp
A3: ORD0002 | B3: CUST029 | C3: PROD018 | D3: East | E3: 96 | F3: 4 | G3: 384 | H3: Credit Card | I3: Delivered | J3: DHL | K3: 44979 | L3: 44981 | N3: =IF(OR(I3="Cancelled",M3<>""),"Yes","No") -> No | O3: =_xlfn.XLOOKUP(Orders!C3,'Product Master'!$A$1:$A$23,'Product Master'!$C$1:$C$23) -> Toys | P3: =IF(L3<>"",L3-K3,"NA") -> 2 | Q3: =_xlfn.XLOOKUP(B3,'Customer Master'!$A$1:$A$50,'Customer Master'!$B$1:$B$50) -> Ava White | R3: {=_xlfn.IFS(P3="NA","NA",P3<=2,"FAST",P3>2,"SLOW")} -> FAST | S3: =_xlfn.XLOOKUP(Orders!C3,'Product Master'!$A$1:$A$23,'Product Master'!$B$1:$B$23) -> Doll House
A4: ORD0003 | B4: CUST021 | C4: PROD013 | D4: South | E4: 194 | F4: 4 | G4: 776 | H4: Credit Card | I4: In Transit | J4: USPS | K4: 45210 | N4: =IF(OR(I4="Cancelled",M4<>""),"Yes","No") -> No | O4: =_xlfn.XLOOKUP(Orders!C4,'Product Master'!$A$1:$A$23,'Product Master'!$C$1:$C$23) -> Home | P4: =IF(L4<>"",L4-K4,"NA") -> NA | Q4: =_xlfn.XLOOKUP(B4,'Customer Master'!$A$1:$A$50,'Customer Master'!$B$1:$B$50) -> Zoe Mitchell | R4: {=_xlfn.IFS(P4="NA","NA",P4<=2,"FAST",P4>2,"SLOW")} -> NA | S4: =_xlfn.XLOOKUP(Orders!C4,'Product Master'!$A$1:$A$23,'Product Master'!$B$1:$B$23) -> Vacuum Cleaner
A5: ORD0004 | B5: CUST044 | C5: PROD013 | D5: North | E5: 196 | F5: 3 | G5: 588 | H5: PayPal | I5: Cancelled | J5: UPS | K5: 45051 | M5: 45057 | N5: =IF(OR(I5="Cancelled",M5<>""),"Yes","No") -> Yes | O5: =_xlfn.XLOOKUP(Orders!C5,'Product Master'!$A$1:$A$23,'Product Master'!$C$1:$C$23) -> Home | P5: =IF(L5<>"",L5-K5,"NA") -> NA | Q5: =_xlfn.XLOOKUP(B5,'Customer Master'!$A$1:$A$50,'Customer Master'!$B$1:$B$50) -> Grace Ward | R5: {=_xlfn.IFS(P5="NA","NA",P5<=2,"FAST",P5>2,"SLOW")} -> NA | S5: =_xlfn.XLOOKUP(Orders!C5,'Product Master'!$A$1:$A$23,'Product Master'!$B$1:$B$23) -> Vacuum Cleaner
A6: ORD0005 | B6: CUST027 | C6: PROD010 | D6: North | E6: 59 | F6: 1 | G6: 59 | H6: PayPal | I6: Delivered | J6: Amazon Logistics | K6: 44959 | L6: 44962 | N6: =IF(OR(I6="Cancelled",M6<>""),"Yes","No") -> No | O6: =_xlfn.XLOOKUP(Orders!C6,'Product Master'!$A$1:$A$23,'Product Master'!$C$1:$C$23) -> Fashion | P6: =IF(L6<>"",L6-K6,"NA") -> 3 | Q6: =_xlfn.XLOOKUP(B6,'Customer Master'!$A$1:$A$50,'Customer Master'!$B$1:$B$50) -> Hazel Brooks | R6: {=_xlfn.IFS(P6="NA","NA",P6<=2,"FAST",P6>2,"SLOW")} -> SLOW | S6: =_xlfn.XLOOKUP(Orders!C6,'Product Master'!$A$1:$A$23,'Product Master'!$B$1:$B$23) -> Jeans
A7: ORD0006 | B7: CUST009 | C7: PROD010 | D7: North | E7: 58 | F7: 4 | G7: 232 | H7: Amazon Pay | I7: Cancelled | J7: DHL | K7: 45231 | M7: 45232 | N7: =IF(OR(I7="Cancelled",M7<>""),"Yes","No") -> Yes | O7: =_xlfn.XLOOKUP(Orders!C7,'Product Master'!$A$1:$A$23,'Product Master'!$C$1:$C$23) -> Fashion | P7: =IF(L7<>"",L7-K7,"NA") -> NA | Q7: =_xlfn.XLOOKUP(B7,'Customer Master'!$A$1:$A$50,'Customer Master'!$B$1:$B$50) -> Jackson Allen | R7: {=_xlfn.IFS(P7="NA","NA",P7<=2,"FAST",P7>2,"SLOW")} -> NA | S7: =_xlfn.XLOOKUP(Orders!C7,'Product Master'!$A$1:$A$23,'Product Master'!$B$1:$B$23) -> Jeans
A8: ORD0007 | B8: CUST042 | C8: PROD020 | D8: Central | E8: 105 | F8: 3 | G8: 315 | H8: Debit Card | I8: Cancelled | J8: DHL | K8: 45152 | M8: 45156 | N8: =IF(OR(I8="Cancelled",M8<>""),"Yes","No") -> Yes | O8: =_xlfn.XLOOKUP(Orders!C8,'Product Master'!$A$1:$A$23,'Product Master'!$C$1:$C$23) -> Electronics | P8: =IF(L8<>"",L8-K8,"NA") -> NA | Q8: =_xlfn.XLOOKUP(B8,'Customer Master'!$A$1:$A$50,'Customer Master'!$B$1:$B$50) -> Noah Wilson | R8: {=_xlfn.IFS(P8="NA","NA",P8<=2,"FAST",P8>2,"SLOW")} -> NA | S8: =_xlfn.XLOOKUP(Orders!C8,'Product Master'!$A$1:$A$23,'Product Master'!$B$1:$B$23) -> Bluetooth Speaker
A9: ORD0008 | B9: CUST019 | C9: PROD021 | D9: West | E9: 37 | F9: 5 | G9: 185 | H9: PayPal | I9: Cancelled | J9: DHL | K9: 45017 | M9: 45022 | N9: =IF(OR(I9="Cancelled",M9<>""),"Yes","No") -> Yes | O9: =_xlfn.XLOOKUP(Orders!C9,'Product Master'!$A$1:$A$23,'Product Master'!$C$1:$C$23) -> Home | P9: =IF(L9<>"",L9-K9,"NA") -> NA | Q9: =_xlfn.XLOOKUP(B9,'Customer Master'!$A$1:$A$50,'Customer Master'!$B$1:$B$50) -> Ava Robinson | R9: {=_xlfn.IFS(P9="NA","NA",P9<=2,"FAST",P9>2,"SLOW")} -> NA | S9: =_xlfn.XLOOKUP(Orders!C9,'Product Master'!$A$1:$A$23,'Product Master'!$B$1:$B$23) -> Wall Clock
A10: ORD0009 | B10: CUST013 | C10: PROD019 | D10: Central | E10: 44 | F10: 2 | G10: 88 | H10: Credit Card | I10: In Transit | J10: Amazon Logistics | K10: 45128 | N10: =IF(OR(I10="Cancelled",M10<>""),"Yes","No") -> No | O10: =_xlfn.XLOOKUP(Orders!C10,'Product Master'!$A$1:$A$23,'Product Master'!$C$1:$C$23) -> Fashion | P10: =IF(L10<>"",L10-K10,"NA") -> NA | Q10: =_xlfn.XLOOKUP(B10,'Customer Master'!$A$1:$A$50,'Customer Master'!$B$1:$B$50) -> Olivia Martinez | R10: {=_xlfn.IFS(P10="NA","NA",P10<=2,"FAST",P10>2,"SLOW")} -> NA | S10: =_xlfn.XLOOKUP(Orders!C10,'Product Master'!$A$1:$A$23,'Product Master'!$B$1:$B$23) -> Formal Shirt
A11: ORD0010 | B11: CUST019 | C11: PROD003 | D11: South | E11: 141 | F11: 4 | G11: 564 | H11: Debit Card | I11: In Transit | J11: DHL | K11: 45289 | N11: =IF(OR(I11="Cancelled",M11<>""),"Yes","No") -> No | O11: =_xlfn.XLOOKUP(Orders!C11,'Product Master'!$A$1:$A$23,'Product Master'!$C$1:$C$23) -> Home | P11: =IF(L11<>"",L11-K11,"NA") -> NA | Q11: =_xlfn.XLOOKUP(B11,'Customer Master'!$A$1:$A$50,'Customer Master'!$B$1:$B$50) -> Ava Robinson | R11: {=_xlfn.IFS(P11="NA","NA",P11<=2,"FAST",P11>2,"SLOW")} -> NA | S11: =_xlfn.XLOOKUP(Orders!C11,'Product Master'!$A$1:$A$23,'Product Master'!$B$1:$B$23) -> Cookware Set
A12: ORD0011 | B12: CUST046 | C12: PROD014 | D12: South | E12: 249 | F12: 1 | G12: 249 | H12: Amazon Pay | I12: Cancelled | J12: USPS | K12: 45050 | M12: 45054 | N12: =IF(OR(I12="Cancelled",M12<>""),"Yes","No") -> Yes | O12: =_xlfn.XLOOKUP(Orders!C12,'Product Master'!$A$1:$A$23,'Product Master'!$C$1:$C$23) -> Electronics | P12: =IF(L12<>"",L12-K12,"NA") -> NA | Q12: =_xlfn.XLOOKUP(B12,'Customer Master'!$A$1:$A$50,'Customer Master'!$B$1:$B$50) -> Emily Johnson | R12: {=_xlfn.IFS(P12="NA","NA",P12<=2,"FAST",P12>2,"SLOW")} -> NA | S12: =_xlfn.XLOOKUP(Orders!C12,'Product Master'!$A$1:$A$23,'Product Master'!$B$1:$B$23) -> Smartwatch
A13: ORD0012 | B13: CUST045 | C13: PROD014 | D13: Central | E13: 247 | F13: 3 | G13: 741 | H13: Amazon Pay | I13: In Transit | J13: FedEx | K13: 45132 | N13: =IF(OR(I13="Cancelled",M13<>""),"Yes","No") -> No | O13: =_xlfn.XLOOKUP(Orders!C13,'Product Master'!$A$1:$A$23,'Product Master'!$C$1:$C$23) -> Electronics | P13: =IF(L13<>"",L13-K13,"NA") -> NA | Q13: =_xlfn.XLOOKUP(B13,'Customer Master'!$A$1:$A$50,'Customer Master'!$B$1:$B$50) -> Emily Johnson | R13: {=_xlfn.IFS(P13="NA","NA",P13<=2,"FAST",P13>2,"SLOW")} -> NA | S13: =_xlfn.XLOOKUP(Orders!C13,'Product Master'!$A$1:$A$23,'Product Master'!$B$1:$B$23) -> Smartwatch
A14: ORD0013 | B14: CUST023 | C14: PROD006 | D14: Central | E14: 96 | F14: 1 | G14: 96 | H14: Apple Pay | I14: Cancelled | J14: Amazon Logistics | K14: 44982 | M14: 44985 | N14: =IF(OR(I14="Cancelled",M14<>""),"Yes","No") -> Yes | O14: =_xlfn.XLOOKUP(Orders!C14,'Product Master'!$A$1:$A$23,'Product Master'!$C$1:$C$23) -> Fashion | P14: =IF(L14<>"",L14-K14,"NA") -> NA | Q14: =_xlfn.XLOOKUP(B14,'Customer Master'!$A$1:$A$50,'Customer Master'!$B$1:$B$50) -> Charlotte Reed | R14: {=_xlfn.IFS(P14="NA","NA",P14<=2,"FAST",P14>2,"SLOW")} -> NA | S14: =_xlfn.XLOOKUP(Orders!C14,'Product Master'!$A$1:$A$23,'Product Master'!$B$1:$B$23) -> Shoes
A15: ORD0014 | B15: CUST033 | C15: PROD017 | D15: West | E15: 74 | F15: 5 | G15: 370 | H15: Apple Pay | I15: Cancelled | J15: Amazon Logistics | K15: 44981 | M15: 44982 | N15: =IF(OR(I15="Cancelled",M15<>""),"Yes","No") -> Yes | O15: =_xlfn.XLOOKUP(Orders!C15,'Product Master'!$A$1:$A$23,'Product Master'!$C$1:$C$23) -> Electronics | P15: =IF(L15<>"",L15-K15,"NA") -> NA | Q15: =_xlfn.XLOOKUP(B15,'Customer Master'!$A$1:$A$50,'Customer Master'!$B$1:$B$50) -> Hazel Rivera | R15: {=_xlfn.IFS(P15="NA","NA",P15<=2,"FAST",P15>2,"SLOW")} -> NA | S15: =_xlfn.XLOOKUP(Orders!C15,'Product Master'!$A$1:$A$23,'Product Master'!$B$1:$B$23) -> Gaming Mouse
A16: ORD0015 | B16: CUST033 | C16: PROD005 | D16: South | E16: 27 | F16: 1 | G16: 27 | H16: Credit Card | I16: Cancelled | J16: Amazon Logistics | K16: 45164 | M16: 45171 | N16: =IF(OR(I16="Cancelled",M16<>""),"Yes","No") -> Yes | O16: =_xlfn.XLOOKUP(Orders!C16,'Product Master'!$A$1:$A$23,'Product Master'!$C$1:$C$23) -> Fashion | P16: =IF(L16<>"",L16-K16,"NA") -> NA | Q16: =_xlfn.XLOOKUP(B16,'Customer Master'!$A$1:$A$50,'Customer Master'!$B$1:$B$50) -> Hazel Rivera | R16: {=_xlfn.IFS(P16="NA","NA",P16<=2,"FAST",P16>2,"SLOW")} -> NA | S16: =_xlfn.XLOOKUP(Orders!C16,'Product Master'!$A$1:$A$23,'Product Master'!$B$1:$B$23) -> T-Shirt
A17: ORD0016 | B17: CUST047 | C17: PROD005 | D17: South | E17: 27 | F17: 3 | G17: 81 | H17: Debit Card | I17: In Transit | J17: Amazon Logistics | K17: 44970 | N17: =IF(OR(I17="Cancelled",M17<>""),"Yes","No") -> No | O17: =_xlfn.XLOOKUP(Orders!C17,'Product Master'!$A$1:$A$23,'Product Master'!$C$1:$C$23) -> Fashion | P17: =IF(L17<>"",L17-K17,"NA") -> NA | Q17: =_xlfn.XLOOKUP(B17,'Customer Master'!$A$1:$A$50,'Customer Master'!$B$1:$B$50) -> Scarlett Murphy | R17: {=_xlfn.IFS(P17="NA","NA",P17<=2,"FAST",P17>2,"SLOW")} -> NA | S17: =_xlfn.XLOOKUP(Orders!C17,'Product Master'!$A$1:$A$23,'Product Master'!$B$1:$B$23) -> T-Shirt
A18: ORD0017 | B18: CUST045 | C18: PROD015 | D18: East | E18: 21 | F18: 3 | G18: 63 | H18: Credit Card | I18: Delivered | J18: DHL | K18: 45105 | L18: 45108 | N18: =IF(OR(I18="Cancelled",M18<>""),"Yes","No") -> No | O18: =_xlfn.XLOOKUP(Orders!C18,'Product Master'!$A$1:$A$23,'Product Master'!$C$1:$C$23) -> Books | P18: =IF(L18<>"",L18-K18,"NA") -> 3 | Q18: =_xlfn.XLOOKUP(B18,'Customer Master'!$A$1:$A$50,'Customer Master'!$B$1:$B$50) -> Emily Johnson | R18: {=_xlfn.IFS(P18="NA","NA",P18<=2,"FAST",P18>2,"SLOW")} -> SLOW | S18: =_xlfn.XLOOKUP(Orders!C18,'Product Master'!$A$1:$A$23,'Product Master'!$B$1:$B$23) -> Novel
A19: ORD0018 | B19: CUST011 | C19: PROD008 | D19: West | E19: 70 | F19: 5 | G19: 350 | H19: PayPal | I19: In Transit | J19: Amazon Logistics | K19: 45258 | N19: =IF(OR(I19="Cancelled",M19<>""),"Yes","No") -> No | O19: =_xlfn.XLOOKUP(Orders!C19,'Product Master'!$A$1:$A$23,'Product Master'!$C$1:$C$23) -> Books | P19: =IF(L19<>"",L19-K19,"NA") -> NA | Q19: =_xlfn.XLOOKUP(B19,'Customer Master'!$A$1:$A$50,'Customer Master'!$B$1:$B$50) -> Mason Hall | R19: {=_xlfn.IFS(P19="NA","NA",P19<=2,"FAST",P19>2,"SLOW")} -> NA | S19: =_xlfn.XLOOKUP(Orders!C19,'Product Master'!$A$1:$A$23,'Product Master'!$B$1:$B$23) -> Textbook
A20: ORD0019 | B20: CUST041 | C20: PROD006 | D20: South | E20: 94 | F20: 4 | G20: 376 | H20: Credit Card | I20: In Transit | J20: USPS | K20: 45163 | N20: =IF(OR(I20="Cancelled",M20<>""),"Yes","No") -> No | O20: =_xlfn.XLOOKUP(Orders!C20,'Product Master'!$A$1:$A$23,'Product Master'!$C$1:$C$23) -> Fashion | P20: =IF(L20<>"",L20-K20,"NA") -> NA | Q20: =_xlfn.XLOOKUP(B20,'Customer Master'!$A$1:$A$50,'Customer Master'!$B$1:$B$50) -> Jacob Price | R20: {=_xlfn.IFS(P20="NA","NA",P20<=2,"FAST",P20>2,"SLOW")} -> NA | S20: =_xlfn.XLOOKUP(Orders!C20,'Product Master'!$A$1:$A$23,'Product Master'!$B$1:$B$23) -> Shoes
A21: ORD0020 | B21: CUST025 | C21: PROD001 | D21: North | E21: 813 | F21: 2 | G21: 1626 | H21: Credit Card | I21: In Transit | J21: FedEx | K21: 45028 | N21: =IF(OR(I21="Cancelled",M21<>""),"Yes","No") -> No | O21: =_xlfn.XLOOKUP(Orders!C21,'Product Master'!$A$1:$A$23,'Product Master'!$C$1:$C$23) -> Electronics | P21: =IF(L21<>"",L21-K21,"NA") -> NA | Q21: =_xlfn.XLOOKUP(B21,'Customer Master'!$A$1:$A$50,'Customer Master'!$B$1:$B$50) -> Emma King | R21: {=_xlfn.IFS(P21="NA","NA",P21<=2,"FAST",P21>2,"SLOW")} -> NA | S21: =_xlfn.XLOOKUP(Orders!C21,'Product Master'!$A$1:$A$23,'Product Master'!$B$1:$B$23) -> Smartphone
A22: ORD0021 | B22: CUST013 | C22: PROD015 | D22: Central | E22: 21 | F22: 4 | G22: 84 | H22: PayPal | I22: In Transit | J22: Amazon Logistics | K22: 45201 | N22: =IF(OR(I22="Cancelled",M22<>""),"Yes","No") -> No | O22: =_xlfn.XLOOKUP(Orders!C22,'Product Master'!$A$1:$A$23,'Product Master'!$C$1:$C$23) -> Books | P22: =IF(L22<>"",L22-K22,"NA") -> NA | Q22: =_xlfn.XLOOKUP(B22,'Customer Master'!$A$1:$A$50,'Customer Master'!$B$1:$B$50) -> Olivia Martinez | R22: {=_xlfn.IFS(P22="NA","NA",P22<=2,"FAST",P22>2,"SLOW")} -> NA | S22: =_xlfn.XLOOKUP(Orders!C22,'Product Master'!$A$1:$A$23,'Product Master'!$B$1:$B$23) -> Novel
A23: ORD0022 | B23: CUST023 | C23: PROD012 | D23: West | E23: 46 | F23: 5 | G23: 230 | H23: PayPal | I23: In Transit | J23: USPS | K23: 45239 | N23: =IF(OR(I23="Cancelled",M23<>""),"Yes","No") -> No | O23: =_xlfn.XLOOKUP(Orders!C23,'Product Master'!$A$1:$A$23,'Product Master'!$C$1:$C$23) -> Home | P23: =IF(L23<>"",L23-K23,"NA") -> NA | Q23: =_xlfn.XLOOKUP(B23,'Customer Master'!$A$1:$A$50,'Customer Master'!$B$1:$B$50) -> Charlotte Reed | R23: {=_xlfn.IFS(P23="NA","NA",P23<=2,"FAST",P23>2,"SLOW")} -> NA | S23: =_xlfn.XLOOKUP(Orders!C23,'Product Master'!$A$1:$A$23,'Product Master'!$B$1:$B$23) -> Lamp
A24: ORD0023 | B24: CUST016 | C24: PROD010 | D24: West | E24: 58 | F24: 3 | G24: 174 | H24: Amazon Pay | I24: Cancelled | J24: Amazon Logistics | K24: 44970 | M24: 44971 | N24: =IF(OR(I24="Cancelled",M24<>""),"Yes","No") -> Yes | O24: =_xlfn.XLOOKUP(Orders!C24,'Product Master'!$A$1:$A$23,'Product Master'!$C$1:$C$23) -> Fashion | P24: =IF(L24<>"",L24-K24,"NA") -> NA | Q24: =_xlfn.XLOOKUP(B24,'Customer Master'!$A$1:$A$50,'Customer Master'!$B$1:$B$50) -> Elijah Lewis | R24: {=_xlfn.IFS(P24="NA","NA",P24<=2,"FAST",P24>2,"SLOW")} -> NA | S24: =_xlfn.XLOOKUP(Orders!C24,'Product Master'!$A$1:$A$23,'Product Master'!$B$1:$B$23) -> Jeans
A25: ORD0024 | B25: CUST028 | C25: PROD006 | D25: West | E25: 96 | F25: 5 | G25: 480 | H25: Amazon Pay | I25: Delivered | J25: Amazon Logistics | K25: 45232 | L25: 45235 | N25: =IF(OR(I25="Cancelled",M25<>""),"Yes","No") -> No | O25: =_xlfn.XLOOKUP(Orders!C25,'Product Master'!$A$1:$A$23,'Product Master'!$C$1:$C$23) -> Fashion | P25: =IF(L25<>"",L25-K25,"NA") -> 3 | Q25: =_xlfn.XLOOKUP(B25,'Customer Master'!$A$1:$A$50,'Customer Master'!$B$1:$B$50) -> Lily Bennett | R25: {=_xlfn.IFS(P25="NA","NA",P25<=2,"FAST",P25>2,"SLOW")} -> SLOW | S25: =_xlfn.XLOOKUP(Orders!C25,'Product Master'!$A$1:$A$23,'Product Master'!$B$1:$B$23) -> Shoes
A26: ORD0025 | B26: CUST040 | C26: PROD002 | D26: South | E26: 43 | F26: 1 | G26: 43 | H26: Debit Card | I26: Delivered | J26: Amazon Logistics | K26: 45074 | L26: 45076 | N26: =IF(OR(I26="Cancelled",M26<>""),"Yes","No") -> No | O26: =_xlfn.XLOOKUP(Orders!C26,'Product Master'!$A$1:$A$23,'Product Master'!$C$1:$C$23) -> Toys | P26: =IF(L26<>"",L26-K26,"NA") -> 2 | Q26: =_xlfn.XLOOKUP(B26,'Customer Master'!$A$1:$A$50,'Customer Master'!$B$1:$B$50) -> Benjamin Clark | R26: {=_xlfn.IFS(P26="NA","NA",P26<=2,"FAST",P26>2,"SLOW")} -> FAST | S26: =_xlfn.XLOOKUP(Orders!C26,'Product Master'!$A$1:$A$23,'Product Master'!$B$1:$B$23) -> Action Figure
A27: ORD0026 | B27: CUST027 | C27: PROD022 | D27: South | E27: 64 | F27: 4 | G27: 256 | H27: Debit Card | I27: Delivered | J27: USPS | K27: 45214 | L27: 45220 | N27: =IF(OR(I27="Cancelled",M27<>""),"Yes","No") -> No | O27: =_xlfn.XLOOKUP(Orders!C27,'Product Master'!$A$1:$A$23,'Product Master'!$C$1:$C$23) -> Fashion | P27: =IF(L27<>"",L27-K27,"NA") -> 6 | Q27: =_xlfn.XLOOKUP(B27,'Customer Master'!$A$1:$A$50,'Customer Master'!$B$1:$B$50) -> Hazel Brooks | R27: {=_xlfn.IFS(P27="NA","NA",P27<=2,"FAST",P27>2,"SLOW")} -> SLOW | S27: =_xlfn.XLOOKUP(Orders!C27,'Product Master'!$A$1:$A$23,'Product Master'!$B$1:$B$23) -> Backpack
A28: ORD0027 | B28: CUST018 | C28: PROD008 | D28: South | E28: 70 | F28: 2 | G28: 140 | H28: Amazon Pay | I28: In Transit | J28: Amazon Logistics | K28: 44942 | N28: =IF(OR(I28="Cancelled",M28<>""),"Yes","No") -> No | O28: =_xlfn.XLOOKUP(Orders!C28,'Product Master'!$A$1:$A$23,'Product Master'!$C$1:$C$23) -> Books | P28: =IF(L28<>"",L28-K28,"NA") -> NA | Q28: =_xlfn.XLOOKUP(B28,'Customer Master'!$A$1:$A$50,'Customer Master'!$B$1:$B$50) -> Grace Scott | R28: {=_xlfn.IFS(P28="NA","NA",P28<=2,"FAST",P28>2,"SLOW")} -> NA | S28: =_xlfn.XLOOKUP(Orders!C28,'Product Master'!$A$1:$A$23,'Product Master'!$B$1:$B$23) -> Textbook
A29: ORD0028 | B29: CUST018 | C29: PROD018 | D29: Central | E29: 97 | F29: 3 | G29: 291 | H29: Credit Card | I29: In Transit | J29: Amazon Logistics | K29: 45208 | N29: =IF(OR(I29="Cancelled",M29<>""),"Yes","No") -> No | O29: =_xlfn.XLOOKUP(Orders!C29,'Product Master'!$A$1:$A$23,'Product Master'!$C$1:$C$23) -> Toys | P29: =IF(L29<>"",L29-K29,"NA") -> NA | Q29: =_xlfn.XLOOKUP(B29,'Customer Master'!$A$1:$A$50,'Customer Master'!$B$1:$B$50) -> Grace Scott | R29: {=_xlfn.IFS(P29="NA","NA",P29<=2,"FAST",P29>2,"SLOW")} -> NA | S29: =_xlfn.XLOOKUP(Orders!C29,'Product Master'!$A$1:$A$23,'Product Master'!$B$1:$B$23) -> Doll House
A30: ORD0029 | B30: CUST007 | C30: PROD021 | D30: East | E30: 37 | F30: 3 | G30: 111 | H30: Apple Pay | I30: Cancelled | J30: DHL | K30: 45206 | M30: 45209 | N30: =IF(OR(I30="Cancelled",M30<>""),"Yes","No") -> Yes | O30: =_xlfn.XLOOKUP(Orders!C30,'Product Master'!$A$1:$A$23,'Product Master'!$C$1:$C$23) -> Home | P30: =IF(L30<>"",L30-K30,"NA") -> NA | Q30: =_xlfn.XLOOKUP(B30,'Customer Master'!$A$1:$A$50,'Customer Master'!$B$1:$B$50) -> Liam Walker | R30: {=_xlfn.IFS(P30="NA","NA",P30<=2,"FAST",P30>2,"SLOW")} -> NA | S30: =_xlfn.XLOOKUP(Orders!C30,'Product Master'!$A$1:$A$23,'Product Master'!$B$1:$B$23) -> Wall Clock
A31: ORD0030 | B31: CUST008 | C31: PROD008 | D31: North | E31: 69 | F31: 5 | G31: 345 | H31: Amazon Pay | I31: In Transit | J31: Amazon Logistics | K31: 44971 | N31: =IF(OR(I31="Cancelled",M31<>""),"Yes","No") -> No | O31: =_xlfn.XLOOKUP(Orders!C31,'Product Master'!$A$1:$A$23,'Product Master'!$C$1:$C$23) -> Books | P31: =IF(L31<>"",L31-K31,"NA") -> NA | Q31: =_xlfn.XLOOKUP(B31,'Customer Master'!$A$1:$A$50,'Customer Master'!$B$1:$B$50) -> Harper Young | R31: {=_xlfn.IFS(P31="NA","NA",P31<=2,"FAST",P31>2,"SLOW")} -> NA | S31: =_xlfn.XLOOKUP(Orders!C31,'Product Master'!$A$1:$A$23,'Product Master'!$B$1:$B$23) -> Textbook
A32: ORD0031 | B32: CUST014 | C32: PROD002 | D32: North | E32: 42 | F32: 5 | G32: 210 | H32: Amazon Pay | I32: In Transit | J32: UPS | K32: 45011 | N32: =IF(OR(I32="Cancelled",M32<>""),"Yes","No") -> No | O32: =_xlfn.XLOOKUP(Orders!C32,'Product Master'!$A$1:$A$23,'Product Master'!$C$1:$C$23) -> Toys | P32: =IF(L32<>"",L32-K32,"NA") -> NA | Q32: =_xlfn.XLOOKUP(B32,'Customer Master'!$A$1:$A$50,'Customer Master'!$B$1:$B$50) -> Harper Young | R32: {=_xlfn.IFS(P32="NA","NA",P32<=2,"FAST",P32>2,"SLOW")} -> NA | S32: =_xlfn.XLOOKUP(Orders!C32,'Product Master'!$A$1:$A$23,'Product Master'!$B$1:$B$23) -> Action Figure
A33: ORD0032 | B33: CUST037 | C33: PROD009 | D33: East | E33: 11 | F33: 5 | G33: 55 | H33: Debit Card | I33: Cancelled | J33: FedEx | K33: 45092 | M33: 45099 | N33: =IF(OR(I33="Cancelled",M33<>""),"Yes","No") -> Yes | O33: =_xlfn.XLOOKUP(Orders!C33,'Product Master'!$A$1:$A$23,'Product Master'!$C$1:$C$23) -> Books | P33: =IF(L33<>"",L33-K33,"NA") -> NA | Q33: =_xlfn.XLOOKUP(B33,'Customer Master'!$A$1:$A$50,'Customer Master'!$B$1:$B$50) -> Emily Johnson | R33: {=_xlfn.IFS(P33="NA","NA",P33<=2,"FAST",P33>2,"SLOW")} -> NA | S33: =_xlfn.XLOOKUP(Orders!C33,'Product Master'!$A$1:$A$23,'Product Master'!$B$1:$B$23) -> Magazine
A34: ORD0033 | B34: CUST016 | C34: PROD005 | D34: South | E34: 27 | F34: 2 | G34: 54 | H34: Apple Pay | I34: Delivered | J34: USPS | K34: 45068 | L34: 45069 | N34: =IF(OR(I34="Cancelled",M34<>""),"Yes","No") -> No | O34: =_xlfn.XLOOKUP(Orders!C34,'Product Master'!$A$1:$A$23,'Product Master'!$C$1:$C$23) -> Fashion | P34: =IF(L34<>"",L34-K34,"NA") -> 1 | Q34: =_xlfn.XLOOKUP(B34,'Customer Master'!$A$1:$A$50,'Customer Master'!$B$1:$B$50) -> Elijah Lewis | R34: {=_xlfn.IFS(P34="NA","NA",P34<=2,"FAST",P34>2,"SLOW")} -> FAST | S34: =_xlfn.XLOOKUP(Orders!C34,'Product Master'!$A$1:$A$23,'Product Master'!$B$1:$B$23) -> T-Shirt
A35: ORD0034 | B35: CUST025 | C35: PROD015 | D35: South | E35: 21 | F35: 1 | G35: 21 | H35: Amazon Pay | I35: In Transit | J35: DHL | K35: 45250 | N35: =IF(OR(I35="Cancelled",M35<>""),"Yes","No") -> No | O35: =_xlfn.XLOOKUP(Orders!C35,'Product Master'!$A$1:$A$23,'Product Master'!$C$1:$C$23) -> Books | P35: =IF(L35<>"",L35-K35,"NA") -> NA | Q35: =_xlfn.XLOOKUP(B35,'Customer Master'!$A$1:$A$50,'Customer Master'!$B$1:$B$50) -> Emma King | R35: {=_xlfn.IFS(P35="NA","NA",P35<=2,"FAST",P35>2,"SLOW")} -> NA | S35: =_xlfn.XLOOKUP(Orders!C35,'Product Master'!$A$1:$A$23,'Product Master'!$B$1:$B$23) -> Novel
A36: ORD0035 | B36: CUST032 | C36: PROD011 | D36: South | E36: 172 | F36: 1 | G36: 172 | H36: PayPal | I36: Delivered | J36: USPS | K36: 45282 | L36: 45286 | N36: =IF(OR(I36="Cancelled",M36<>""),"Yes","No") -> No | O36: =_xlfn.XLOOKUP(Orders!C36,'Product Master'!$A$1:$A$23,'Product Master'!$C$1:$C$23) -> Electronics | P36: =IF(L36<>"",L36-K36,"NA") -> 4 | Q36: =_xlfn.XLOOKUP(B36,'Customer Master'!$A$1:$A$50,'Customer Master'!$B$1:$B$50) -> Luke Gray | R36: {=_xlfn.IFS(P36="NA","NA",P36<=2,"FAST",P36>2,"SLOW")} -> SLOW | S36: =_xlfn.XLOOKUP(Orders!C36,'Product Master'!$A$1:$A$23,'Product Master'!$B$1:$B$23) -> Headphones
A37: ORD0036 | B37: CUST014 | C37: PROD016 | D37: North | E37: 212 | F37: 3 | G37: 636 | H37: Amazon Pay | I37: In Transit | J37: UPS | K37: 45130 | N37: =IF(OR(I37="Cancelled",M37<>""),"Yes","No") -> No | O37: =_xlfn.XLOOKUP(Orders!C37,'Product Master'!$A$1:$A$23,'Product Master'!$C$1:$C$23) -> Home | P37: =IF(L37<>"",L37-K37,"NA") -> NA | Q37: =_xlfn.XLOOKUP(B37,'Customer Master'!$A$1:$A$50,'Customer Master'!$B$1:$B$50) -> Harper Young | R37: {=_xlfn.IFS(P37="NA","NA",P37<=2,"FAST",P37>2,"SLOW")} -> NA | S37: =_xlfn.XLOOKUP(Orders!C37,'Product Master'!$A$1:$A$23,'Product Master'!$B$1:$B$23) -> Cookware Set Pro
A38: ORD0037 | B38: CUST044 | C38: PROD002 | D38: East | E38: 41 | F38: 4 | G38: 164 | H38: Credit Card | I38: Delivered | J38: Amazon Logistics | K38: 45216 | L38: 45221 | N38: =IF(OR(I38="Cancelled",M38<>""),"Yes","No") -> No | O38: =_xlfn.XLOOKUP(Orders!C38,'Product Master'!$A$1:$A$23,'Product Master'!$C$1:$C$23) -> Toys | P38: =IF(L38<>"",L38-K38,"NA") -> 5 | Q38: =_xlfn.XLOOKUP(B38,'Customer Master'!$A$1:$A$50,'Customer Master'!$B$1:$B$50) -> Grace Ward | R38: {=_xlfn.IFS(P38="NA","NA",P38<=2,"FAST",P38>2,"SLOW")} -> SLOW | S38: =_xlfn.XLOOKUP(Orders!C38,'Product Master'!$A$1:$A$23,'Product Master'!$B$1:$B$23) -> Action Figure
A39: ORD0038 | B39: CUST028 | C39: PROD007 | D39: North | E39: 32 | F39: 2 | G39: 64 | H39: Debit Card | I39: Cancelled | J39: FedEx | K39: 45160 | M39: 45162 | N39: =IF(OR(I39="Cancelled",M39<>""),"Yes","No") -> Yes | O39: =_xlfn.XLOOKUP(Orders!C39,'Product Master'!$A$1:$A$23,'Product Master'!$C$1:$C$23) -> Toys | P39: =IF(L39<>"",L39-K39,"NA") -> NA | Q39: =_xlfn.XLOOKUP(B39,'Customer Master'!$A$1:$A$50,'Customer Master'!$B$1:$B$50) -> Lily Bennett | R39: {=_xlfn.IFS(P39="NA","NA",P39<=2,"FAST",P39>2,"SLOW")} -> NA | S39: =_xlfn.XLOOKUP(Orders!C39,'Product Master'!$A$1:$A$23,'Product Master'!$B$1:$B$23) -> Puzzle
A40: ORD0039 | B40: CUST024 | C40: PROD022 | D40: East | E40: 66 | F40: 2 | G40: 132 | H40: Apple Pay | I40: In Transit | J40: DHL | K40: 45262 | N40: =IF(OR(I40="Cancelled",M40<>""),"Yes","No") -> No | O40: =_xlfn.XLOOKUP(Orders!C40,'Product Master'!$A$1:$A$23,'Product Master'!$C$1:$C$23) -> Fashion | P40: =IF(L40<>"",L40-K40,"NA") -> NA | Q40: =_xlfn.XLOOKUP(B40,'Customer Master'!$A$1:$A$50,'Customer Master'!$B$1:$B$50) -> Scarlett Murphy | R40: {=_xlfn.IFS(P40="NA","NA",P40<=2,"FAST",P40>2,"SLOW")} -> NA | S40: =_xlfn.XLOOKUP(Orders!C40,'Product Master'!$A$1:$A$23,'Product Master'!$B$1:$B$23) -> Backpack
...

Sheet Product Master
A1: Product ID | B1: Product Name | C1: Category | D1: Cost Price | E1: Description
A2: PROD001 | B2: Smartphone | C2: Electronics | D2: 749 | E2: Latest model with 5G, dual SIM, and OLED display
A3: PROD002 | B3: Action Figure | C3: Toys | D3: 39 | E3: Collectible superhero action figure for ages 8+
A4: PROD003 | B4: Cookware Set | C4: Home | D4: 129 | E4: Non-stick 5-piece cookware set for daily use
A5: PROD004 | B5: Leg Set | C5: Toys | D5: 59 | E5: 300-piece creative building block toy set
A6: PROD005 | B6: T-Shirt | C6: Fashion | D6: 25 | E6: Cotton t-shirt, available in multiple colors
A7: PROD006 | B7: Shoes | C7: Fashion | D7: 89 | E7: Casual wear shoes for men and women
A8: PROD007 | B8: Puzzle | C8: Toys | D8: 29 | E8: 1000-piece jigsaw puzzle
A9: PROD008 | B9: Textbook | C9: Books | D9: 65 | E9: University-level textbook on computer science
A10: PROD009 | B10: Magazine | C10: Books | D10: 10 | E10: Monthly lifestyle magazine
A11: PROD010 | B11: Jeans | C11: Fashion | D11: 55 | E11: Slim fit denim jeans with stretch
A12: PROD011 | B12: Headphones | C12: Electronics | D12: 159 | E12: Wireless noise-cancelling over-ear headphones
A13: PROD012 | B13: Lamp | C13: Home | D13: 42 | E13: LED desk lamp with dimmable light
... A23: PROD022 | B23: Backpack | C23: Fashion | D23: 60 | E23: Waterproof backpack with laptop compartment

Sheet Region Master
A1: Region | B1: Sales Target
A2: Central | B2: 97500
A3: East | B3: 50500
A4: North | B4: 105000
A5: South | B5: 91500
A6: West | B6: 90750

Sheet Customer Master
A1: Customer ID | B1: Customer Name | C1: Customer Type | D1: City | E1: State
A2: CUST001 | B2: James Miller | C2: Business | D2: New York | E2: New York
A3: CUST002 | B3: Emily Johnson | C3: Prime | D3: Seattle | E3: Washington
A4: CUST003 | B4: Ethan Davis | C4: Prime | D4: Austin | E4: Texas
A5: CUST004 | B5: Noah Wilson | C5: Prime | D5: San Francisco | E5: California
A6: CUST005 | B6: Olivia Martinez | C6: Prime | D6: Seattle | E6: Washington
A7: CUST006 | B7: Ava Robinson | C7: Prime | D7: Chicago | E7: Illinois
A8: CUST007 | B8: Liam Walker | C8: Prime | D8: San Francisco | E8: California
A9: CUST008 | B9: Harper Young | C9: Business | D9: Dallas | E9: Texas
A10: CUST009 | B10: Jackson Allen | C10: Business | D10: Seattle | E10: Washington
A11: CUST010 | B11: Charlotte Harris | C11: Prime | D11: Chicago | E11: Illinois
A12: CUST011 | B12: Mason Hall | C12: Business | D12: Miami | E12: Florida
... A50: CUST049 | B50: Hazel Gray | C50: Business | D50: Chicago | E50: Illinois

Sheet 2.1
A3: Sum of Total Amount | B3: Column Labels
A4: Row Labels | B4: Books | C4: Electronics | D4: Fashion | E4: Home | F4: Toys | G4: Grand Total
A5: Central | B5: 84 | C5: 2662 | D5: 210 | E5: 2063 | F5: 437 | G5: 5456
A6: East | B6: 394 | C6: 365 | D6: 711 | E6: 741 | F6: 1424 | G6: 3635
A7: North | B7: 464 | C7: 6522 | D7: 788 | E7: 2131 | F7: 586 | G7: 10491
A8: South | B8: 423 | C8: 3938 | D8: 1032 | E8: 1881 | F8: 43 | G8: 7317
A9: West | B9: 350 | C9: 1722 | D9: 1131 | E9: 4135 | F9: 1021 | G9: 8359
A10: Grand Total | B10: 1715 | C10: 15209 | D10: 3872 | E10: 10951 | F10: 3511 | G10: 35258

Sheet 2.2
A3: Row Labels | B3: Count of Order ID
A4: Cancelled | B4: 30
A5: Delivered | B5: 34
A6: In Transit | B6: 36
A7: Grand Total | B7: 100

Sheet 4.2
A3: Row Labels | B3: Sum of Total Amount
A4: Delivered | B4: 13656
A5: Grand Total | B5: 13656

Sheet 2.3,2.4
A1: Payment Method | B1: (All)
A2: Product category | B2: (All)
A4: Row Labels | B4: Average of Avg. delivery date
A5: Central | B5: 4.2
A6: East | B6: 4.25
A7: North | B7: 3.625
A8: South | B8: 3.3333333
A9: West | B9: 3.4285714
A10: Grand Total | B10: 3.7647059

Sheet 4.3.1
A3: Sum of Total Amount
A4: 35258

Sheet 4.1
A3: Count of Order ID | B3: Column Labels
A4: Row Labels | B4: No | C4: Yes | D4: Grand Total
A5: Central | B5: 9 | C5: 5 | D5: 14 | E5: =GETPIVOTDATA("Order ID",$A$3,"Region","Central","Is cancelled","Yes")/GETPIVOTDATA("Order ID",$A$3,"Region","Central") -> 0.35714286
A6: East | B6: 15 | C6: 3 | D6: 18 | E6: =GETPIVOTDATA("Order ID",$A$3,"Region","East","Is cancelled","Yes")/GETPIVOTDATA("Order ID",$A$3,"Region","East") -> 0.16666667
A7: North | B7: 15 | C7: 10 | D7: 25 | E7: =GETPIVOTDATA("Order ID",$A$3,"Region","North","Is cancelled","Yes")/GETPIVOTDATA("Order ID",$A$3,"Region","North") -> 0.4
A8: South | B8: 16 | C8: 4 | D8: 20 | E8: =GETPIVOTDATA("Order ID",$A$3,"Region","South","Is cancelled","Yes")/GETPIVOTDATA("Order ID",$A$3,"Region","South") -> 0.2
A9: West | B9: 15 | C9: 8 | D9: 23 | E9: =GETPIVOTDATA("Order ID",$A$3,"Region","West","Is cancelled","Yes")/GETPIVOTDATA("Order ID",$A$3,"Region","West") -> 0.34782609
A10: Grand Total | B10: 70 | C10: 30 | D10: 100

Sheet 4.3.2
B3: Column Labels
B4: FAST | C4: NA | D4: SLOW | E4: Grand Total | F4: % of fast deliveries
A5: Count of Order ID | B5: 11 | C5: 66 | D5: 23 | E5: 100 | F5: =GETPIVOTDATA("Order ID",$A$3,"Delivery performance","FAST")/(GETPIVOTDATA("Order ID",$A$3,"Delivery performance","FAST")+GETPIVOTDATA("Order ID",$A$3,"Delivery performance","SLOW")) -> 0.32352941

Sheet 4.3.3
A3: Row Labels | B3: Sum of Total Amount
A4: North | B4: 10491
A5: South | B5: 7317
A6: West | B6: 8359
A7: Grand Total | B7: 26167

Sheet 4.3.4
A3: Row Labels | B3: Count of Total Amount
A4: Leg Set | B4: 8
A5: T-Shirt | B5: 8
A6: Grand Total | B6: 16

Sheet Region
A3: Row Labels | B3: Sum of Total Amount | C3: HIGH | D3: LOW
A4: Central | B4: 5456 | C4: =IF(B4>7000,B4,NA()) -> #N/A | D4: =IF(B4<7000,B4,NA()) -> 5456
A5: East | B5: 3635 | C5: =IF(B5>7000,B5,NA()) -> #N/A | D5: =IF(B5<7000,B5,NA()) -> 3635
A6: North | B6: 10491 | C6: =IF(B6>7000,B6,NA()) -> 10491 | D6: =IF(B6<7000,B6,NA()) -> #N/A
A7: South | B7: 7317 | C7: =IF(B7>7000,B7,NA()) -> 7317 | D7: =IF(B7<7000,B7,NA()) -> #N/A
A8: West | B8: 8359 | C8: =IF(B8>7000,B8,NA()) -> 8359 | D8: =IF(B8<7000,B8,NA()) -> #N/A
A9: Grand Total | B9: 35258 | C9: =IF(B9>7000,B9,NA()) -> 35258 | D9: =IF(B9<7000,B9,NA()) -> #N/A
A13: Central | B13: 5456 | C13: =IF(B13>7000,B13,NA()) -> #N/A | D13: =IF(B13<7000,B13,NA()) -> 5456
A14: East | B14: 3635 | C14: =IF(B14>7000,B14,NA()) -> #N/A | D14: =IF(B14<7000,B14,NA()) -> 3635
A15: North | B15: 10491 | C15: =IF(B15>7000,B15,NA()) -> 10491 | D15: =IF(B15<7000,B15,NA()) -> #N/A
A16: South | B16: 7317 | C16: =IF(B16>7000,B16,NA()) -> 7317 | D16: =IF(B16<7000,B16,NA()) -> #N/A
A17: West | B17: 8359 | C17: =IF(B17>7000,B17,NA()) -> 8359 | D17: =IF(B17<7000,B17,NA()) -> #N/A

Sheet Payment method
A3: Row Labels | B3: Sum of Total Amount
A4: Amazon Pay | B4: 4719
A5: Apple Pay | B5: 6144
A6: Credit Card | B6: 9398
A7: Debit Card | B7: 8348
A8: PayPal | B8: 6649
A9: Grand Total | B9: 35258

Sheet Delivery status
A3: Row Labels | B3: Sum of Total Amount
A4: Cancelled | B4: 6961
A5: Delivered | B5: 13656
A6: In Transit | B6: 14641
A7: Grand Total | B7: 35258

Sheet Sales by months
A3: Row Labels | B3: Sum of Total Amount
A4: Jan | B4: 1099
A5: Feb | B5: 3712
A6: Mar | B6: 905
A7: Apr | B7: 2637
A8: May | B8: 4940
A9: Jun | B9: 2599
A10: Jul | B10: 3315
A11: Aug | B11: 782
A12: Sep | B12: 1570
A13: Oct | B13: 2920
A14: Nov | B14: 6312
A15: Dec | B15: 4467
A16: Grand Total | B16: 35258

Sheet DASHBOARD
K3: SALES DASHBOARD
AT8: Sum of Total Amount
AT9: 35258
AR10: 35

Sheet Brainstorming reflection
B2: Brainstorming Reflection
B4: ● What is the most successful product category in terms of revenue?
B5: Ans. Electronics
B8: ● Which region has the highest order cancellation rate?
B9: Ans. North
B12: ● How many orders were delivered within 2 days?
B13: Ans. 11
B16: ● How has the use of XLOOKUP simplified cross-sheet analysis?
B17: Ans. By using xlookup I can bring multiple datas from other data sheets to the sheet I am using.
B20: ● What recommendations would you give to improve delivery performance?
B21: Ans. 1) As the data suggests most of the orders are in transit so we have to investigate the reason behind the orders which are in transit. (2) We have to pick the delivery partners which have performed better in each regions.
